<?xml version="1.0" encoding="utf-8"?>
<!-- This URDF was automatically created by SolidWorks to URDF Exporter! Originally created by Stephen Brawner (brawner@gmail.com) 
     Commit Version: 1.5.1-0-g916b5db  Build Version: 1.5.7152.31018
     For more information, please see http://wiki.ros.org/sw_urdf_exporter -->
<robot name="car_simulation">
  <gazebo>
    <plugin
      name="gazebo_ros_control"
      filename="libgazebo_ros_control.so">
      <robotNamespace>/car</robotNamespace>
    </plugin>
  </gazebo>
  <link name="dummy"></link>
  <joint name="dummy_joint" type="fixed">
    <parent link="dummy"/>
    <child link="base_link"/>
  </joint>
  <link
    name="base_link">
    <inertial>
      <origin
        xyz="-0.00074513 -0.11739 0.055785"
        rpy="0 0 0" />
      <mass
        value="8" />
      <inertia
        ixx="0.55567"
        ixy="-0.00039063"
        ixz="-0.0032652"
        iyy="0.57391"
        iyz="-0.019683"
        izz="0.61063" />
    </inertial>
    <visual>
      <origin
        xyz="0 0 0"
        rpy="0 0 0" />
      <geometry>
        <mesh
          filename="package://car_simulation/meshes/base_link.STL" />
      </geometry>
      <material
        name="">
        <color
          rgba="0.79216 0.81961 0.93333 1" />
      </material>
    </visual>
    <collision>
      <origin
        xyz="0 0 0"
        rpy="0 0 0" />
      <geometry>
        <mesh
          filename="package://car_simulation/meshes/base_link.STL" />
      </geometry>
    </collision>
  </link>
  <gazebo reference="LF_wheel">
    <material>Gazebo/Orange</material>
  </gazebo>
  <link
    name="LF_wheel">
    <inertial>
      <origin
        xyz="-0.032026 -1.3878E-17 -5.5511E-17"
        rpy="0 0 0" />
      <mass
        value="0.49554" />
      <inertia
        ixx="0.0018121"
        ixy="2.1263E-22"
        ixz="1.9263E-20"
        iyy="0.00096656"
        iyz="5.0211E-21"
        izz="0.00096656" />
    </inertial>
    <visual>
      <origin
        xyz="0 0 0"
        rpy="0 0 0" />
      <geometry>
        <mesh
          filename="package://car_simulation/meshes/LF_wheel.STL" />
      </geometry>
      <material
        name="">
        <color
          rgba="0.79216 0.81961 0.93333 1" />
      </material>
    </visual>
    <collision>
      <origin
        xyz="0 0 0"
        rpy="0 0 0" />
      <geometry>
        <mesh
          filename="package://car_simulation/meshes/LF_wheel.STL" />
      </geometry>
    </collision>
  </link>
  <joint
    name="LF_wheel_jnt"
    type="continuous">
    <origin
      xyz="-0.27192 0.1695 -0.1241"
      rpy="0 0 0" />
    <parent
      link="base_link" />
    <child
      link="LF_wheel" />
    <axis
      xyz="1 0 0" />
    <limit
      effort="0"
      velocity="35" />
  </joint>
  <gazebo reference="LB_wheel">
    <material>Gazebo/Orange</material>
  </gazebo>
  <link
    name="LB_wheel">
    <inertial>
      <origin
        xyz="-0.032026 2.7756E-17 2.7756E-17"
        rpy="0 0 0" />
      <mass
        value="0.49554" />
      <inertia
        ixx="0.0018121"
        ixy="2.1243E-20"
        ixz="3.9097E-21"
        iyy="0.00096656"
        iyz="9.7862E-20"
        izz="0.00096656" />
    </inertial>
    <visual>
      <origin
        xyz="0 0 0"
        rpy="0 0 0" />
      <geometry>
        <mesh
          filename="package://car_simulation/meshes/LB_wheel.STL" />
      </geometry>
      <material
        name="">
        <color
          rgba="0.79216 0.81961 0.93333 1" />
      </material>
    </visual>
    <collision>
      <origin
        xyz="0 0 0"
        rpy="0 0 0" />
      <geometry>
        <mesh
          filename="package://car_simulation/meshes/LB_wheel.STL" />
      </geometry>
    </collision>
  </link>
  <joint
    name="LB_wheel_jnt"
    type="continuous">
    <origin
      xyz="-0.27192 -0.2695 -0.1241"
      rpy="1.5708 0 0" />
    <parent
      link="base_link" />
    <child
      link="LB_wheel" />
    <axis
      xyz="1 0 0" />
    <limit
      effort="0"
      velocity="35" />
  </joint>
  <gazebo reference="RF_wheel">
    <material>Gazebo/Orange</material>
  </gazebo>
  <link
    name="RF_wheel">
    <inertial>
      <origin
        xyz="0.032026 6.9389E-17 0"
        rpy="0 0 0" />
      <mass
        value="0.49554" />
      <inertia
        ixx="0.0018121"
        ixy="1.1755E-35"
        ixz="2.5636E-20"
        iyy="0.00096656"
        iyz="3.8844E-35"
        izz="0.00096656" />
    </inertial>
    <visual>
      <origin
        xyz="0 0 0"
        rpy="0 0 0" />
      <geometry>
        <mesh
          filename="package://car_simulation/meshes/RF_wheel.STL" />
      </geometry>
      <material
        name="">
        <color
          rgba="0.79216 0.81961 0.93333 1" />
      </material>
    </visual>
    <collision>
      <origin
        xyz="0 0 0"
        rpy="0 0 0" />
      <geometry>
        <mesh
          filename="package://car_simulation/meshes/RF_wheel.STL" />
      </geometry>
    </collision>
  </link>
  <joint
    name="RF_wheel_jnt"
    type="continuous">
    <origin
      xyz="0.27208 0.1695 -0.1241"
      rpy="1.5708 0 0" />
    <parent
      link="base_link" />
    <child
      link="RF_wheel" />
    <axis
      xyz="-1 0 0" />
    <limit
      effort="0"
      velocity="35" />
  </joint>
  <gazebo reference="RB_wheel">
    <material>Gazebo/Orange</material>
  </gazebo>
  <link
    name="RB_wheel">
    <inertial>
      <origin
        xyz="0.032026 6.9389E-17 0"
        rpy="0 0 0" />
      <mass
        value="0.49554" />
      <inertia
        ixx="0.0018121"
        ixy="3.3987E-36"
        ixz="1.3212E-20"
        iyy="0.00096656"
        iyz="-4.9432E-36"
        izz="0.00096656" />
    </inertial>
    <visual>
      <origin
        xyz="0 0 0"
        rpy="0 0 0" />
      <geometry>
        <mesh
          filename="package://car_simulation/meshes/RB_wheel.STL" />
      </geometry>
      <material
        name="">
        <color
          rgba="0.79216 0.81961 0.93333 1" />
      </material>
    </visual>
    <collision>
      <origin
        xyz="0 0 0"
        rpy="0 0 0" />
      <geometry>
        <mesh
          filename="package://car_simulation/meshes/RB_wheel.STL" />
      </geometry>
    </collision>
  </link>
  <joint
    name="RB_wheel_jnt"
    type="continuous">
    <origin
      xyz="0.27208 -0.2695 -0.1241"
      rpy="1.5708 0 0" />
    <parent
      link="base_link" />
    <child
      link="RB_wheel" />
    <axis
      xyz="-1 0 0" />
    <limit
      effort="0"
      velocity="35" />
  </joint>
</robot>